Workbook

Sheet 订单列表
A1: id | B1: salesOrgId_name | D1: agentId_name | F1: saleDepartmentId_name | G1: corpContactUserName | H1: productName | I1: subQty | J1: qty | K1: qtyName | L1: payMoney | M1: reserveid_reservecust_code | N1: reserveid_reservecust_name | O1: orderDefineCharacter!erpOrderNumber | P1: orderDefineCharacter!erpPoStatus | Q1: orderDefineCharacter!needDeliveryDate | R1: orderDetails_createDate | S1: creatorId | T1: cCreator | U1: creator | V1: createTime
A2: 主体ID | B2: 销售组织 | C2: 客戶編碼 | D2: 客户 | E2: 客名 | F2: 销售部门 | G2: 销售业务员 | H2: 商品名称 | I2: 销售数量 | J2: 数量 | K2: 主计量 | L2: 合计含税金额 | M2: 线索客户编码 | N2: 线索客户名称 | O2: ERP订单号 | P2: ERP订单状态 | Q2: 要求送货日期 | R2: 创建时间 | S2: 创建人 | T2: 创建人 | U2: 创建人 | V2: 创建时间 | W2: 商品編碼 | X2: 小類編碼 | Y2: 小類 | Z2: 客戶屬性 | AA2: 訂單總金額
A3: 2588256797291708421 | B3: 香港事业部 | C3: NFT00.000168 | D3: 明記凍肉 | E3: 明記 | F3: 分销业务冻品水产部销售部 | G3: 凌靖翔 | H3: 遼寧欣城琵琶腿130-150G|10KG(5KG*2) | I3: 1 | J3: 10 | K3: 千克 | L3: 128 | O3: 14796327 | P3: 已登记 | Q3: 46223 | R3: 46223.416 | S3: 2387140048816439304 | U3: 明記凍肉 | V3: 46223.416 | W3: =VLOOKUP(H3,物料編碼!A:B,2,0) -> 1300624103 | X3: 1300624 | Y3: =VLOOKUP(X3,物料編碼!D:G,4,0) -> 琵琶腿 | Z3: =VLOOKUP(C3,客戶屬性1!A:C,2,0) -> 明记冻肉 | AA3: =IF(COUNTIF($O$1:O3,O3)=1,L3,0) -> 128
A4: 2588253747864928264 | B4: 香港事业部 | C4: NFT00.003177 | D4: 翎凰凍肉有限公司 | E4: 翎凰 | F4: 分销业务冻品水产部销售部 | G4: 凌靖翔 | H4: 至尊梅肉|25KG | I4: 20 | J4: 500 | K4: 千克 | L4: 19647.35 | O4: 14797265 | P4: 已登记 | Q4: 46224 | R4: 46223.412 | S4: 2485989227956797442 | U4: 翎凰 | V4: 46223.412 | W4: =VLOOKUP(H4,物料編碼!A:B,2,0) -> 1300101043 | X4: 1300101 | Y4: =VLOOKUP(X4,物料編碼!D:G,4,0) -> 一號肉 | Z4: =VLOOKUP(C4,客戶屬性1!A:C,2,0) -> 翎凰冻肉有限公司 | AA4: =IF(COUNTIF($O$1:O4,O4)=1,L4,0) -> 19647.35
A5: 2588253747864928264 | B5: 香港事业部 | C5: NFT00.003177 | D5: 翎凰凍肉有限公司 | E5: 翎凰 | F5: 分销业务冻品水产部销售部 | G5: 凌靖翔 | H5: 金鷹面精肉|25KG | I5: 3 | J5: 75 | K5: 千克 | L5: 19647.35 | O5: 14797265 | P5: 已登记 | Q5: 46224 | R5: 46223.412 | S5: 2485989227956797442 | U5: 翎凰 | V5: 46223.412 | W5: =VLOOKUP(H5,物料編碼!A:B,2,0) -> 1300109002 | X5: 1300109 | Y5: =VLOOKUP(X5,物料編碼!D:G,4,0) -> 面精肉 | Z5: =VLOOKUP(C5,客戶屬性1!A:C,2,0) -> 翎凰冻肉有限公司 | AA5: =IF(COUNTIF($O$1:O5,O5)=1,L5,0) -> 0
A6: 2588227608717033474 | B6: 香港事业部 | C6: NFT00.000185 | D6: 萬駿貿易公司 | E6: 萬駿 | F6: 分销业务冻品水产部销售部 | G6: 岑美玉 | H6: 至尊梅肉|25KG | I6: 10 | J6: 250 | K6: 千克 | L6: 8875 | O6: 14796239 | P6: 已登记 | Q6: 46223 | R6: 46223.377 | S6: 2489640319525584898 | U6: 萬駿 | V6: 46223.377 | W6: =VLOOKUP(H6,物料編碼!A:B,2,0) -> 1300101043 | X6: 1300101 | Y6: =VLOOKUP(X6,物料編碼!D:G,4,0) -> 一號肉 | Z6: =VLOOKUP(C6,客戶屬性1!A:C,2,0) -> 万骏贸易公司 | AA6: =IF(COUNTIF($O$1:O6,O6)=1,L6,0) -> 8875
A7: 2586807400471199744 | B7: 香港事业部 | C7: NFT00.000230 | D7: 恆輝貿易公司 | E7: 恆輝 | F7: 分销业务冻品水产部销售部 | G7: 凌靖翔 | H7: 遼寧欣城帶骨雞全腿 280-300G|15KG | I7: 1 | J7: 15 | K7: 千克 | L7: 1962.15 | O7: 14796981 | P7: 已登记 | Q7: 46223 | R7: 46221.463 | S7: 2460695736053923847 | U7: 恆輝 | V7: 46221.463 | W7: =VLOOKUP(H7,物料編碼!A:B,2,0) -> 1300603040 | X7: 1300603 | Y7: =VLOOKUP(X7,物料編碼!D:G,4,0) -> 帶骨全腿 | Z7: =VLOOKUP(C7,客戶屬性1!A:C,2,0) -> 恒辉贸易公司 | AA7: =IF(COUNTIF($O$1:O7,O7)=1,L7,0) -> 1962.15
A8: 2586807400471199744 | B8: 香港事业部 | C8: NFT00.000230 | D8: 恆輝貿易公司 | E8: 恆輝 | F8: 分销业务冻品水产部销售部 | G8: 凌靖翔 | H8: 遼寧銘川帶皮腿扒|15KG (250克+/塊) | I8: 8 | J8: 120 | K8: 千克 | L8: 1962.15 | O8: 14796981 | P8: 已登记 | Q8: 46223 | R8: 46221.463 | S8: 2460695736053923847 | U8: 恆輝 | V8: 46221.463 | W8: =VLOOKUP(H8,物料編碼!A:B,2,0) -> 1300607014 | X8: 1300607 | Y8: =VLOOKUP(X8,物料編碼!D:G,4,0) -> 帶皮腿扒 | Z8: =VLOOKUP(C8,客戶屬性1!A:C,2,0) -> 恒辉贸易公司 | AA8: =IF(COUNTIF($O$1:O8,O8)=1,L8,0) -> 0
A9: 2586800004514447366 | B9: 香港事业部 | C9: NFT00.000230 | D9: 恆輝貿易公司 | E9: 恆輝 | F9: 分销业务冻品水产部销售部 | G9: 凌靖翔 | H9: 金鷹面精肉|25KG | I9: 5 | J9: 125 | K9: 千克 | L9: 4091.5 | O9: 14796079 | P9: 已登记 | Q9: 46223 | R9: 46221.453 | S9: 2393862608937549832 | U9: 許先生 | V9: 46221.453 | W9: =VLOOKUP(H9,物料編碼!A:B,2,0) -> 1300109002 | X9: 1300109 | Y9: =VLOOKUP(X9,物料編碼!D:G,4,0) -> 面精肉 | Z9: =VLOOKUP(C9,客戶屬性1!A:C,2,0) -> 恒辉贸易公司 | AA9: =IF(COUNTIF($O$1:O9,O9)=1,L9,0) -> 4091.5
A10: 2586783279934865417 | B10: 香港事业部 | C10: NFT00.000168 | D10: 明記凍肉 | E10: 明記 | F10: 分销业务冻品水产部销售部 | G10: 凌靖翔 | H10: 遼寧欣城琵琶腿130-150G|10KG(5KG*2) | I10: 1 | J10: 10 | K10: 千克 | L10: 128 | O10: 14796067 | P10: 已登记 | Q10: 46221 | R10: 46221.431 | S10: 2387140048816439304 | U10: 明記凍肉 | V10: 46221.431 | W10: =VLOOKUP(H10,物料編碼!A:B,2,0) -> 1300624103 | X10: 1300624 | Y10: =VLOOKUP(X10,物料編碼!D:G,4,0) -> 琵琶腿 | Z10: =VLOOKUP(C10,客戶屬性1!A:C,2,0) -> 明记冻肉 | AA10: =IF(COUNTIF($O$1:O10,O10)=1,L10,0) -> 128
A11: 2586779474593841159 | B11: 香港事业部 | C11: NFT00.000337 | D11: 新城發食品有限公司 | E11: 新城發 | F11: 分销业务冻品水产部销售部 | G11: 许至邦 | H11: 金鷹面精肉|25KG | I11: 4 | J11: 100 | K11: 千克 | L11: 3273.2 | O11: 14796066 | P11: 已登记 | Q11: 46223 | R11: 46221.426 | S11: 2387140160485589002 | U11: 新城發 | V11: 46221.426 | W11: =VLOOKUP(H11,物料編碼!A:B,2,0) -> 1300109002 | X11: 1300109 | Y11: =VLOOKUP(X11,物料編碼!D:G,4,0) -> 面精肉 | Z11: =VLOOKUP(C11,客戶屬性1!A:C,2,0) -> 新城发食品有限公司 | AA11: =IF(COUNTIF($O$1:O11,O11)=1,L11,0) -> 3273.2
A12: 2586778452368556034 | B12: 香港事业部 | C12: NFT00.000230 | D12: 恆輝貿易公司 | E12: 恆輝 | F12: 分销业务冻品水产部销售部 | G12: 凌靖翔 | H12: 山東鴨胸肉|10KG(200-220克/塊) | I12: 1 | J12: 10 | K12: 千克 | L12: 132 | O12: 14796068 | P12: 已输入 | Q12: 46221 | R12: 46221.424 | S12: 2393862608937549832 | U12: 許先生 | V12: 46221.424 | W12: =VLOOKUP(H12,物料編碼!A:B,2,0) -> 1300903005 | X12: 1300903 | Y12: =VLOOKUP(X12,物料編碼!D:G,4,0) -> 生鴨胸 | Z12: =VLOOKUP(C12,客戶屬性1!A:C,2,0) -> 恒辉贸易公司 | AA12: =IF(COUNTIF($O$1:O12,O12)=1,L12,0) -> 132
A13: 2586236015178940424 | B13: 香港事业部 | C13: NFT00.000357 | D13: 三明有限公司 | E13: 三明 | F13: 分销业务冻品水产部销售部 | G13: 张淑燕 | H13: 金鷹梅肉|25KG | I13: 10 | J13: 250 | K13: 千克 | L13: 6790 | O13: 14796814 | P13: 已登记 | Q13: 46221 | R13: 46220.693 | S13: 2460735601940365319 | U13: 三明 | V13: 46220.693 | W13: =VLOOKUP(H13,物料編碼!A:B,2,0) -> 1300101018 | X13: 1300101 | Y13: =VLOOKUP(X13,物料編碼!D:G,4,0) -> 一號肉 | Z13: =VLOOKUP(C13,客戶屬性1!A:C,2,0) -> 三明有限公司 | AA13: =IF(COUNTIF($O$1:O13,O13)=1,L13,0) -> 6790
A14: 2586171985806491649 | B14: 香港事业部 | C14: NFT00.002474 | D14: 明記冷凍食品有限公司 | E14: 明記冷凍 | F14: 分销业务冻品水产部销售部 | G14: 岑美玉 | H14: 至尊梅肉|25KG | I14: 6 | J14: 150 | K14: 千克 | L14: 5410.47 | O14: 14796679 | P14: 已登记 | Q14: 46223 | R14: 46220.607 | S14: 2387140615752122374 | U14: 明記(荃灣) | V14: 46220.607 | W14: =VLOOKUP(H14,物料編碼!A:B,2,0) -> 1300101043 | X14: 1300101 | Y14: =VLOOKUP(X14,物料編碼!D:G,4,0) -> 一號肉 | Z14: =VLOOKUP(C14,客戶屬性1!A:C,2,0) -> MING KEE | AA14: =IF(COUNTIF($O$1:O14,O14)=1,L14,0) -> 5410.47
... A119: 2580311116384043008 | B119: 香港事业部 | C119: NFT00.003034 | D119: 豪氣有限公司 | E119: 豪氣 | F119: 分销业务冻品水产部销售部 | G119: 萧景新 | H119: 高峰柱裝羊卷肉|20KG | I119: 2 | J119: 40 | K119: 千克 | L119: 2631.89 | O119: 14788757 | P119: 已登记 | Q119: 46213 | R119: 46212.71 | S119: 2454793274168180740 | U119: 豪氣有限公司 | V119: 46212.71 | W119: =VLOOKUP(H119,物料編碼!A:B,2,0) -> 1300511002 | X119: 1300511 | Y119: =VLOOKUP(X119,物料編碼!D:G,4,0) -> 羊卷肉 | Z119: =VLOOKUP(C119,客戶屬性1!A:C,2,0) -> 豪气有限公司 | AA119: =IF(COUNTIF($O$1:O119,O119)=1,L119,0) -> 0
A120: 2580303076228333576 | B120: 香港事业部 | C120: NFT00.002854 | D120: 新柏霖有限公司 | E120: 新柏霖 | F120: 分销业务冻品水产部销售部 | G120: 谭小君 | H120: 溫氏黃油中3雞|24.5KG (1.3-1.4kg/只,共18只)(抄碼)-停用 | I120: 2 | J120: 24 | K120: 千克 | L120: 571.2 | P120: 开立 | Q120: 46213 | R120: 46212.699 | S120: 2562335467095195663 | U120: 運興泰有限公司 | V120: 46212.699 | W120: =VLOOKUP(H120,物料編碼!A:B,2,0) -> #N/A | X120: #N/A | Y120: =VLOOKUP(X120,物料編碼!D:G,4,0) -> #N/A | Z120: =VLOOKUP(C120,客戶屬性1!A:C,2,0) -> 新柏霖有限公司 | AA120: =IF(COUNTIF($O$1:O120,O120)=1,L120,0) -> 0
A121: 2580259018430742529 | B121: 香港事业部 | C121: NFT00.002854 | D121: 新柏霖有限公司 | E121: 新柏霖 | F121: 分销业务冻品水产部销售部 | G121: 谭小君 | H121: 伊美佳12支骨法式羊排|20KG | I121: 2 | J121: 40 | K121: 千克 | L121: 3096.8 | O121: 14788695 | P121: 已登记 | Q121: 46213 | R121: 46212.64 | S121: 2562335467095195663 | U121: 運興泰有限公司 | V121: 46212.64 | W121: =VLOOKUP(H121,物料編碼!A:B,2,0) -> 1300501029 | X121: 1300501 | Y121: =VLOOKUP(X121,物料編碼!D:G,4,0) -> 羊排 | Z121: =VLOOKUP(C121,客戶屬性1!A:C,2,0) -> 新柏霖有限公司 | AA121: =IF(COUNTIF($O$1:O121,O121)=1,L121,0) -> 3096.8
A122: 2580232355273768964 | B122: 香港事业部 | C122: NFT00.000230 | D122: 恆輝貿易公司 | E122: 恆輝 | F122: 分销业务冻品水产部销售部 | G122: 凌靖翔 | H122: 金鷹寸骨|10KG (1K*10包) | I122: 1 | J122: 10 | K122: 千克 | L122: 480 | O122: 14788292 | P122: 已登记 | Q122: 46213 | R122: 46212.604 | S122: 2393863201643036677 | U122: 許先生 | V122: 46212.604 | W122: =VLOOKUP(H122,物料編碼!A:B,2,0) -> 1300111003 | X122: 1300111 | Y122: =VLOOKUP(X122,物料編碼!D:G,4,0) -> 寸骨 | Z122: =VLOOKUP(C122,客戶屬性1!A:C,2,0) -> 恒辉贸易公司 | AA122: =IF(COUNTIF($O$1:O122,O122)=1,L122,0) -> 480
A123: 2580219779609526279 | B123: 香港事业部 | C123: NFT00.000230 | D123: 恆輝貿易公司 | E123: 恆輝 | F123: 分销业务冻品水产部销售部 | G123: 凌靖翔 | H123: 遼寧銘川帶皮腿扒|15KG (300克+/塊) | I123: 4 | J123: 60 | K123: 千克 | L123: 886.8 | O123: 14788269 | P123: 已登记 | Q123: 46213 | R123: 46212.587 | S123: 2393862608937549832 | U123: 許先生 | V123: 46212.587 | W123: =VLOOKUP(H123,物料編碼!A:B,2,0) -> 1300607015 | X123: 1300607 | Y123: =VLOOKUP(X123,物料編碼!D:G,4,0) -> 帶皮腿扒 | Z123: =VLOOKUP(C123,客戶屬性1!A:C,2,0) -> 恒辉贸易公司 | AA123: =IF(COUNTIF($O$1:O123,O123)=1,L123,0) -> 886.8
A124: 2580157073110073347 | B124: 香港事业部 | C124: NFT00.000774 | D124: 新昌 | E124: 新昌 | F124: 分销业务冻品水产部 | G124: 张淑燕 | H124: 至尊梅肉|25KG | I124: 1 | J124: 25 | K124: 千克 | L124: 3200.65 | O124: 14788240 | P124: 已登记 | Q124: 46213 | R124: 46212.503 | S124: 2387140254974869510 | U124: 新昌 | V124: 46212.503 | W124: =VLOOKUP(H124,物料編碼!A:B,2,0) -> 1300101043 | X124: 1300101 | Y124: =VLOOKUP(X124,物料編碼!D:G,4,0) -> 一號肉 | Z124: =VLOOKUP(C124,客戶屬性1!A:C,2,0) -> 新昌冻肉 | AA124: =IF(COUNTIF($O$1:O124,O124)=1,L124,0) -> 3200.65
A125: 2580157073110073347 | B125: 香港事业部 | C125: NFT00.000774 | D125: 新昌 | E125: 新昌 | F125: 分销业务冻品水产部 | G125: 张淑燕 | H125: 金鷹寸骨|10KG (1K*10包) | I125: 1 | J125: 10 | K125: 千克 | L125: 3200.65 | O125: 14788240 | P125: 已登记 | Q125: 46213 | R125: 46212.503 | S125: 2387140254974869510 | U125: 新昌 | V125: 46212.503 | W125: =VLOOKUP(H125,物料編碼!A:B,2,0) -> 1300111003 | X125: 1300111 | Y125: =VLOOKUP(X125,物料編碼!D:G,4,0) -> 寸骨 | Z125: =VLOOKUP(C125,客戶屬性1!A:C,2,0) -> 新昌冻肉 | AA125: =IF(COUNTIF($O$1:O125,O125)=1,L125,0) -> 0
A126: 2580157073110073347 | B126: 香港事业部 | C126: NFT00.000774 | D126: 新昌 | E126: 新昌 | F126: 分销业务冻品水产部 | G126: 张淑燕 | H126: 金鷹面精肉|25KG | I126: 1 | J126: 25 | K126: 千克 | L126: 3200.65 | O126: 14788240 | P126: 已登记 | Q126: 46213 | R126: 46212.503 | S126: 2387140254974869510 | U126: 新昌 | V126: 46212.503 | W126: =VLOOKUP(H126,物料編碼!A:B,2,0) -> 1300109002 | X126: 1300109 | Y126: =VLOOKUP(X126,物料編碼!D:G,4,0) -> 面精肉 | Z126: =VLOOKUP(C126,客戶屬性1!A:C,2,0) -> 新昌冻肉 | AA126: =IF(COUNTIF($O$1:O126,O126)=1,L126,0) -> 0
A127: 2580157073110073347 | B127: 香港事业部 | C127: NFT00.000774 | D127: 新昌 | E127: 新昌 | F127: 分销业务冻品水产部 | G127: 张淑燕 | H127: 遼寧欣城帶骨雞全腿 300-320G|15KG | I127: 2 | J127: 30 | K127: 千克 | L127: 3200.65 | O127: 14788240 | P127: 已登记 | Q127: 46213 | R127: 46212.503 | S127: 2387140254974869510 | U127: 新昌 | V127: 46212.503 | W127: =VLOOKUP(H127,物料編碼!A:B,2,0) -> 1300603041 | X127: 1300603 | Y127: =VLOOKUP(X127,物料編碼!D:G,4,0) -> 帶骨全腿 | Z127: =VLOOKUP(C127,客戶屬性1!A:C,2,0) -> 新昌冻肉 | AA127: =IF(COUNTIF($O$1:O127,O127)=1,L127,0) -> 0
A128: 2580157073110073347 | B128: 香港事业部 | C128: NFT00.000774 | D128: 新昌 | E128: 新昌 | F128: 分销业务冻品水产部 | G128: 张淑燕 | H128: 遼寧銘川帶皮腿扒|15KG (300克+/塊) | I128: 3 | J128: 45 | K128: 千克 | L128: 3200.65 | O128: 14788240 | P128: 已登记 | Q128: 46213 | R128: 46212.503 | S128: 2387140254974869510 | U128: 新昌 | V128: 46212.503 | W128: =VLOOKUP(H128,物料編碼!A:B,2,0) -> 1300607015 | X128: 1300607 | Y128: =VLOOKUP(X128,物料編碼!D:G,4,0) -> 帶皮腿扒 | Z128: =VLOOKUP(C128,客戶屬性1!A:C,2,0) -> 新昌冻肉 | AA128: =IF(COUNTIF($O$1:O128,O128)=1,L128,0) -> 0
A129: 2580121596680208389 | B129: 香港事业部 | C129: NFT00.000116 | D129: 新協興凍肉食品公司 | E129: 新協興 | F129: 分销业务冻品水产部销售部 | G129: 凌靖翔 | H129: 金鷹面精肉|25KG | I129: 3 | J129: 75 | K129: 千克 | L129: 5601.07 | O129: 14788176 | P129: 已登记 | Q129: 46212 | R129: 46212.455 | S129: 2387139997276831755 | U129: 新協興凍肉食品公司 | V129: 46212.455 | W129: =VLOOKUP(H129,物料編碼!A:B,2,0) -> 1300109002 | X129: 1300109 | Y129: =VLOOKUP(X129,物料編碼!D:G,4,0) -> 面精肉 | Z129: =VLOOKUP(C129,客戶屬性1!A:C,2,0) -> 新协兴冻肉食品公司 | AA129: =IF(COUNTIF($O$1:O129,O129)=1,L129,0) -> 5601.07
A130: 2580121596680208389 | B130: 香港事业部 | C130: NFT00.000116 | D130: 新協興凍肉食品公司 | E130: 新協興 | F130: 分销业务冻品水产部销售部 | G130: 凌靖翔 | H130: 高峰網裝羊肩卷肉| 18KG | I130: 1 | J130: 18 | K130: 千克 | L130: 5601.07 | O130: 14788176 | P130: 已登记 | Q130: 46212 | R130: 46212.455 | S130: 2387139997276831755 | U130: 新協興凍肉食品公司 | V130: 46212.455 | W130: =VLOOKUP(H130,物料編碼!A:B,2,0) -> 1300503009 | X130: 1300503 | Y130: =VLOOKUP(X130,物料編碼!D:G,4,0) -> 羊肩卷肉 | Z130: =VLOOKUP(C130,客戶屬性1!A:C,2,0) -> 新协兴冻肉食品公司 | AA130: =IF(COUNTIF($O$1:O130,O130)=1,L130,0) -> 0
A131: 2580121596680208389 | B131: 香港事业部 | C131: NFT00.000116 | D131: 新協興凍肉食品公司 | E131: 新協興 | F131: 分销业务冻品水产部销售部 | G131: 凌靖翔 | H131: 高峰四號肉 25KG | I131: 2 | J131: 50 | K131: 千克 | L131: 5601.07 | O131: 14788176 | P131: 已登记 | Q131: 46212 | R131: 46212.455 | S131: 2387139997276831755 | U131: 新協興凍肉食品公司 | V131: 46212.455 | W131: =VLOOKUP(H131,物料編碼!A:B,2,0) -> 1300104005 | X131: 1300104 | Y131: =VLOOKUP(X131,物料編碼!D:G,4,0) -> 四號肉 | Z131: =VLOOKUP(C131,客戶屬性1!A:C,2,0) -> 新协兴冻肉食品公司 | AA131: =IF(COUNTIF($O$1:O131,O131)=1,L131,0) -> 0
A132: 2580121596680208389 | B132: 香港事业部 | C132: NFT00.000116 | D132: 新協興凍肉食品公司 | E132: 新協興 | F132: 分销业务冻品水产部销售部 | G132: 凌靖翔 | H132: 溫氏黃油中1雞|22KG (1.6-1.7kg/只)/共13只(抄码)-停用 | I132: 3 | J132: 36 | K132: 千克 | L132: 5601.07 | O132: 14788176 | P132: 已登记 | Q132: 46212 | R132: 46212.455 | S132: 2387139997276831755 | U132: 新協興凍肉食品公司 | V132: 46212.455 | W132: =VLOOKUP(H132,物料編碼!A:B,2,0) -> #N/A | X132: #N/A | Y132: =VLOOKUP(X132,物料編碼!D:G,4,0) -> #N/A | Z132: =VLOOKUP(C132,客戶屬性1!A:C,2,0) -> 新协兴冻肉食品公司 | AA132: =IF(COUNTIF($O$1:O132,O132)=1,L132,0) -> 0
A133: 2580082117317754887 | B133: 香港事业部 | C133: 15MYKD.80036688 | D133: 美亞食品貿易有限公司 | E133: 美亞 | F133: 分销业务冻品水产部销售部 | G133: 许至邦 | H133: 遼寧欣城帶皮腿扒|15KG (250-300/塊) | I133: 25 | J133: 375 | K133: 千克 | L133: 5542.5 | O133: 14788043 | P133: 已登记 | Q133: 46213 | R133: 46212.402 | S133: 2471774913431601159 | U133: 美亞 | V133: 46212.402 | W133: =VLOOKUP(H133,物料編碼!A:B,2,0) -> 1300607016 | X133: 1300607 | Y133: =VLOOKUP(X133,物料編碼!D:G,4,0) -> 帶皮腿扒 | Z133: =VLOOKUP(C133,客戶屬性1!A:C,2,0) -> 美亚食品贸易有限公司 | AA133: =IF(COUNTIF($O$1:O133,O133)=1,L133,0) -> 5542.5
A134: 2580077410033598467 | B134: 香港事业部 | C134: NFT00.000230 | D134: 恆輝貿易公司 | E134: 恆輝 | F134: 分销业务冻品水产部销售部 | G134: 凌靖翔 | H134: 華英全淨膛鴨|12KG (1.5KG/只) | I134: 1 | J134: 12 | K134: 千克 | L134: 126 | O134: 14788021 | P134: 已登记 | Q134: 46212 | R134: 46212.395 | S134: 2393862875225522194 | U134: 許先生 | V134: 46212.395 | W134: =VLOOKUP(H134,物料編碼!A:B,2,0) -> 1300901003 | X134: 1300901 | Y134: =VLOOKUP(X134,物料編碼!D:G,4,0) -> 整鴨 | Z134: =VLOOKUP(C134,客戶屬性1!A:C,2,0) -> 恒辉贸易公司 | AA134: =IF(COUNTIF($O$1:O134,O134)=1,L134,0) -> 126
A135: 2580074979105177600 | B135: 香港事业部 | C135: NFT00.000230 | D135: 恆輝貿易公司 | E135: 恆輝 | F135: 分销业务冻品水产部销售部 | G135: 凌靖翔 | H135: 金鷹寸骨|10KG (1K*10包) | I135: 1 | J135: 10 | K135: 千克 | L135: 480 | O135: 14788003 | P135: 已登记 | Q135: 46212 | R135: 46212.392 | S135: 2393862608937549832 | U135: 許先生 | V135: 46212.392 | W135: =VLOOKUP(H135,物料編碼!A:B,2,0) -> 1300111003 | X135: 1300111 | Y135: =VLOOKUP(X135,物料編碼!D:G,4,0) -> 寸骨 | Z135: =VLOOKUP(C135,客戶屬性1!A:C,2,0) -> 恒辉贸易公司 | AA135: =IF(COUNTIF($O$1:O135,O135)=1,L135,0) -> 480
A136: 2579520052127596544 | B136: 香港事业部 | C136: NFT00.000230 | D136: 恆輝貿易公司 | E136: 恆輝 | F136: 分销业务冻品水产部销售部 | G136: 凌靖翔 | H136: 華英鴨胸肉|10KG 200-220G/塊) | I136: 1 | J136: 10 | K136: 千克 | L136: 136 | O136: 14787864 | P136: 已登记 | Q136: 46212 | R136: 46211.644 | S136: 2393862608937549832 | U136: 許先生 | V136: 46211.644 | W136: =VLOOKUP(H136,物料編碼!A:B,2,0) -> 1300903002 | X136: 1300903 | Y136: =VLOOKUP(X136,物料編碼!D:G,4,0) -> 生鴨胸 | Z136: =VLOOKUP(C136,客戶屬性1!A:C,2,0) -> 恒辉贸易公司 | AA136: =IF(COUNTIF($O$1:O136,O136)=1,L136,0) -> 136
A137: 2579510500143398921 | B137: 香港事业部 | C137: NFT00.000229 | D137: 駿利貿易公司 | E137: 駿利 | F137: 分销业务冻品水产部销售部 | G137: 张淑燕 | H137: 金鷹寸骨|10KG (1K*10包) | I137: 2 | J137: 20 | K137: 千克 | L137: 950.4 | O137: 14787856 | P137: 已登记 | Q137: 46212 | R137: 46211.631 | S137: 2387140091766112280 | U137: 駿利貿易公司 | V137: 46211.631 | W137: =VLOOKUP(H137,物料編碼!A:B,2,0) -> 1300111003 | X137: 1300111 | Y137: =VLOOKUP(X137,物料編碼!D:G,4,0) -> 寸骨 | Z137: =VLOOKUP(C137,客戶屬性1!A:C,2,0) -> 骏利贸易公司 | AA137: =IF(COUNTIF($O$1:O137,O137)=1,L137,0) -> 950.4
A138: 2579458977692647424 | B138: 香港事业部 | C138: NFT00.000774 | D138: 新昌 | E138: 新昌 | F138: 分销业务冻品水产部 | G138: 张淑燕 | H138: 山東煙熏鴨胸肉|10KG (200-220G/塊)日文包裝 | I138: 1 | J138: 10 | K138: 千克 | L138: 1307.52 | O138: 14786983 | P138: 已登记 | Q138: 46212 | R138: 46211.562 | S138: 2387140254974869510 | U138: 新昌 | V138: 46211.562 | W138: =VLOOKUP(H138,物料編碼!A:B,2,0) -> 1300904016 | X138: 1300904 | Y138: =VLOOKUP(X138,物料編碼!D:G,4,0) -> 煙熏鴨胸 | Z138: =VLOOKUP(C138,客戶屬性1!A:C,2,0) -> 新昌冻肉 | AA138: =IF(COUNTIF($O$1:O138,O138)=1,L138,0) -> 1307.52
A139: 2579458977692647424 | B139: 香港事业部 | C139: NFT00.000774 | D139: 新昌 | E139: 新昌 | F139: 分销业务冻品水产部 | G139: 张淑燕 | H139: 遼寧欣城帶骨雞全腿 300-320G|15KG | I139: 2 | J139: 30 | K139: 千克 | L139: 1307.52 | O139: 14786983 | P139: 已登记 | Q139: 46212 | R139: 46211.562 | S139: 2387140254974869510 | U139: 新昌 | V139: 46211.562 | W139: =VLOOKUP(H139,物料編碼!A:B,2,0) -> 1300603041 | X139: 1300603 | Y139: =VLOOKUP(X139,物料編碼!D:G,4,0) -> 帶骨全腿 | Z139: =VLOOKUP(C139,客戶屬性1!A:C,2,0) -> 新昌冻肉 | AA139: =IF(COUNTIF($O$1:O139,O139)=1,L139,0) -> 0
A140: 2579458977692647424 | B140: 香港事业部 | C140: NFT00.000774 | D140: 新昌 | E140: 新昌 | F140: 分销业务冻品水产部 | G140: 张淑燕 | H140: 遼寧銘川帶皮腿扒|15KG (300克+/塊) | I140: 3 | J140: 45 | K140: 千克 | L140: 1307.52 | O140: 14786983 | P140: 已登记 | Q140: 46212 | R140: 46211.562 | S140: 2387140254974869510 | U140: 新昌 | V140: 46211.562 | W140: =VLOOKUP(H140,物料編碼!A:B,2,0) -> 1300607015 | X140: 1300607 | Y140: =VLOOKUP(X140,物料編碼!D:G,4,0) -> 帶皮腿扒 | Z140: =VLOOKUP(C140,客戶屬性1!A:C,2,0) -> 新昌冻肉 | AA140: =IF(COUNTIF($O$1:O140,O140)=1,L140,0) -> 0
A141: 2579410324303118340 | B141: 香港事业部 | C141: NFT00.002551 | D141: 溢利食品(香港)有限公司 | E141: 溢利 | F141: 分销业务冻品水产部销售部 | G141: 凌靖翔 | H141: 中國紅布腸|20KG | I141: 1 | J141: 20 | K141: 千克 | L141: 490 | O141: 14787788 | P141: 已登记 | Q141: 46212 | R141: 46211.496 | S141: 2471768556880003081 | U141: 溢利 | V141: 46211.496 | W141: =VLOOKUP(H141,物料編碼!A:B,2,0) -> 1300114011 | X141: 1300114 | Y141: =VLOOKUP(X141,物料編碼!D:G,4,0) -> 熟食 | Z141: =VLOOKUP(C141,客戶屬性1!A:C,2,0) -> 溢利食品(香港)有限公司 | AA141: =IF(COUNTIF($O$1:O141,O141)=1,L141,0) -> 490
A142: 2579408382977900548 | B142: 香港事业部 | C142: NFT00.000229 | D142: 駿利貿易公司 | E142: 駿利 | F142: 分销业务冻品水产部销售部 | G142: 张淑燕 | H142: 高峰法式小切羊排 |10KG | I142: 2 | J142: 20 | K142: 千克 | L142: 2059.2 | O142: 14786921 | P142: 已登记 | Q142: 46212 | R142: 46211.494 | S142: 2387140091766112280 | U142: 駿利貿易公司 | V142: 46211.494 | W142: =VLOOKUP(H142,物料編碼!A:B,2,0) -> 1300501022 | X142: 1300501 | Y142: =VLOOKUP(X142,物料編碼!D:G,4,0) -> 羊排 | Z142: =VLOOKUP(C142,客戶屬性1!A:C,2,0) -> 骏利贸易公司 | AA142: =IF(COUNTIF($O$1:O142,O142)=1,L142,0) -> 2059.2
A143: 2579369152769687552 | B143: 香港事业部 | C143: NFT00.000168 | D143: 明記凍肉 | E143: 明記 | F143: 分销业务冻品水产部销售部 | G143: 凌靖翔 | H143: 遼寧欣城琵琶腿130-150G|10KG(5KG*2) | I143: 2 | J143: 20 | K143: 千克 | L143: 256 | O143: 14787733 | P143: 已登记 | Q143: 46211 | R143: 46211.441 | S143: 2387140048816439304 | U143: 明記凍肉 | V143: 46211.441 | W143: =VLOOKUP(H143,物料編碼!A:B,2,0) -> 1300624103 | X143: 1300624 | Y143: =VLOOKUP(X143,物料編碼!D:G,4,0) -> 琵琶腿 | Z143: =VLOOKUP(C143,客戶屬性1!A:C,2,0) -> 明记冻肉 | AA143: =IF(COUNTIF($O$1:O143,O143)=1,L143,0) -> 256
A144: 2579356972219367427 | B144: 香港事业部 | C144: NFT00.003177 | D144: 翎凰凍肉有限公司 | E144: 翎凰 | F144: 分销业务冻品水产部销售部 | G144: 凌靖翔 | H144: 至尊梅肉|25KG | I144: 20 | J144: 500 | K144: 千克 | L144: 17217.5 | O144: 14786829 | P144: 已登记 | Q144: 46212 | R144: 46211.425 | S144: 2485989227956797442 | U144: 翎凰 | V144: 46211.424 | W144: =VLOOKUP(H144,物料編碼!A:B,2,0) -> 1300101043 | X144: 1300101 | Y144: =VLOOKUP(X144,物料編碼!D:G,4,0) -> 一號肉 | Z144: =VLOOKUP(C144,客戶屬性1!A:C,2,0) -> 翎凰冻肉有限公司 | AA144: =IF(COUNTIF($O$1:O144,O144)=1,L144,0) -> 17217.5
...

Sheet 客戶屬性1
A1: 客户账号 | B1: 客户名称 | C1: 客戶性質 | E1: 客戶編碼 | F1: 客名
A2: 15MYKD.80011410 | B2: 源富食品有限公司 | C2: 加工 | E2: NFT00.002547 | F2: 先進
A3: 15MYKD.80011601 | B3: 富记烧腊 | C3: 燒臘 | E3: NFT00.000230 | F3: 恆輝
A4: 15MYKD.80022017 | B4: 金源烧腊茶餐厅有限公司 | C4: 燒臘 | E4: NFT00.000168 | F4: 明記
A5: 15MYKD.HHD01 | B5: 合兴香港有限公司 | C5: 加工 | E5: NFT00.002551 | F5: 溢利
A6: 15MYKD.KSH05 | B6: 佳城兴业有限公司/火炭 | C6: 加工 | E6: NFT00.000229 | F6: 駿利
A7: 15MYKD.SHT01 | B7: 顺兴冻肉公司 | C7: 凍肉店 | E7: NFT00.000169 | F7: 福源
A8: NFT00.000008 | B8: 金翠烧味餐厅有限公司(深) | C8: 小餐飲 | E8: NFT00.003074 | F8: 信隆
A9: NFT00.000079 | B9: 明兴冻肉食品有限公司 | C9: 加工 | E9: NFT00.000759 | F9: 天恆
A10: NFT00.000100 | B10: 赵增记 | C10: 加工 | E10: NFT00.002474 | F10: 明記冷凍
A11: NFT00.000101 | B11: 李圻记 | C11: 凍肉店 | E11: 15MYKD.KSH05 | F11: 佳城興業 | H11: 1
A12: NFT00.000126 | B12: 华新鱼翅海产公司 | C12: 加工 | E12: NFT00.000774 | F12: 新昌
A13: NFT00.000151 | B13: 天壹食品有限公司 | C13: 加工 | E13: NFT00.000232 | F13: 興利號
A14: NFT00.000154 | B14: 利宝冻肉有限公司 | C14: 加工 | E14: NFT00.000090 | F14: 姚氏
A15: NFT00.000155 | B15: 冠环球(郭)有限公司 | C15: 加工 | E15: 15MYKD.80036688 | F15: 美亞
A16: NFT00.000233 | B16: 利丰肉食海产有限公司 | C16: 加工 | E16: NFT00.000091 | F16: 恆昌
A17: NFT00.000236 | B17: 富成环球海产有限公司 | C17: 加工 | E17: NFT00.000185 | F17: 萬駿
A18: NFT00.000371 | B18: 万事利食品有限公司 | C18: 加工 | E18: NFT00.003177 | F18: 翎凰
A19: NFT00.000759 | B19: 天恒食品有限公司 | C19: 飛機 | E19: NFT00.003034 | F19: 豪氣
A20: NFT00.001511 | B20: 福永行贸易有限公司 | C20: 加工 | E20: NFT00.003421 | F20: 峻星
A21: NFT00.001643 | B21: 永丰泰有限公司 | C21: 加工 | E21: NFT00.000283 | F21: 國威
A22: NFT00.001963 | B22: 金兴冻肉公司 | C22: 加工 | E22: NFT00.000385 | F22: 誠信
A23: NFT00.001984 | B23: 星朗食品有限公司 | C23: 加工 | E23: NFT00.002160 | F23: 鴻興
... A64: NFT00.002170 | B64: 新森林 (NEW FOREST HOLDING LIMITED) | C64: 小餐飲 | E64: NFT00.000057 | F64: 大利
A65: NFT00.002235 | B65: 会所1号 时尚康山 | C65: 小餐飲
A66: NFT00.002236 | B66: 会所1号 尖东荟 | C66: 小餐飲
A67: NFT00.002282 | B67: 海洋公园 | C67: 小餐飲
A68: NFT00.002437 | B68: EURO GO GO LIMITED | C68: 小餐飲
A69: NFT00.002459 | B69: 卓思创意有限公司 | C69: 飛機
A70: NFT00.002482 | B70: 太子餐厅有限公司 | C70: 小餐飲
A71: NFT00.002627 | B71: 神农氏资源有限公司 | C71: 加工
A72: NFT00.002628 | B72: 歌富有限公司 | C72: 小餐飲
A73: NFT00.002983 | B73: 丰甞亚洲有限公司 | C73: 加工
A74: NFT00.002987 | B74: 东华三院萧旺李满福幼儿园 | C74: 社會機構
A75: NFT00.003005 | B75: 佳记集团食品有限公司 | C75: 飛機
A76: NFT00.003029 | B76: 力嘉食品有限公司 | C76: 加工
... A475: NFTZ0.000066 | B475: 华润(集团)有限公司 | C475: 小餐飲

Sheet 客戶編碼
A1: 客户 | C1: 客户
A2: 客户编码 | B2: 客户名称 | C2: 客户编码
A3: NFT00.003623 | B3: 野火樂園食品公司 | C3: NFT00.003623
A4: NFT00.003523 | B4: 煒豐食品發展有限公司 | C4: NFT00.003523
A5: NFT00.000031 | B5: 華豐燒臘有限公司 | C5: NFT00.000031
A6: NFT00.001891 | B6: 雲和凍肉有限公司 | C6: NFT00.001891
A7: NFT00.000786 | B7: 海皇國際有限公司 | C7: NFT00.000786
A8: NFT00.003567 | B8: 冠興凍肉(香港)有限公司 | C8: NFT00.003567
A9: NFT00.000091 | B9: 恆昌凍肉食品有限公司 | C9: NFT00.000091
A10: NFT00.003505 | B10: 盛記肉食 | C10: NFT00.003505
A11: 15MYKD.LKK03 | B11: 梁九記父子有限公司 | C11: 15MYKD.LKK03
A12: NFT00.003090 | B12: 佳味食品貿易有限公司 | C12: NFT00.003090
A13: NFT00.003123 | B13: 麒勇有限公司 | C13: NFT00.003123
... A425: NFT00.003501 | B425: 明記海鮮食品有限公司 | C425: NFT00.003501

Sheet 物料編碼
A1: 物料說明 | B1: 物料編碼 | D1: 管理分类列表
A2: 優質梅肉|25KG | B2: 1300101007 | D2: 编码 | E2: 大類 | F2: 中类 | G2: 小类 | H2: 商品数量 | I2: 商品分类
A3: 金鷹梅肉|25KG | B3: 1300101018 | D3: 1300101 | E3: 中貨 | F3: 中國豬肉 | G3: 一號肉 | I3: 急凍肉類
A4: 中國梅肉|25KG | B4: 1300101040 | D4: 1300102 | E4: 中貨 | F4: 中國豬肉 | G4: 二號肉 | I4: 急凍肉類
A5: 至尊梅肉|25KG | B5: 1300101043 | D5: 1300103 | E5: 中貨 | F5: 中國豬肉 | G5: 三號肉 | I5: 急凍肉類
A6: 至尊梅肉|25KG(14-15條) | B6: 1300101051 | D6: 1300104 | E6: 中貨 | F6: 中國豬肉 | G6: 四號肉 | I6: 急凍肉類
A7: 精品面精肉|25KG | B7: 1300109012 | D7: 1300106 | E7: 中貨 | F7: 中國豬肉 | G7: 脊膘 | I7: 急凍肉類
A8: 巴西 Seara 豬梅肉∣19KG（抄碼） | B8: 1300201041 | D8: 1300107 | E8: 中貨 | F8: 中國豬肉 | G8: 大排 | I8: 急凍肉類
A9: 巴西Seara有骨大排∣19KG（抄碼） | B9: 1300207068 | D9: 1300109 | E9: 中貨 | F9: 中國豬肉 | G9: 面精肉 | I9: 急凍肉類
A10: 巴西Seara削骨豬大排∣19KG（抄碼） | B10: 1300207070 | D10: 1300111 | E10: 中貨 | F10: 中國豬肉 | G10: 寸骨 | I10: 急凍肉類
A11: 巴西 Anglo 牛孖筋|26KG(抄碼) | B11: 1300406048 | D11: 1300114 | E11: 中貨 | F11: 中國豬肉 | G11: 熟食 | I11: 急凍肉類
A12: 巴西Mataboi 牛尾∣26KG(抄碼) | B12: 1300421016 | D12: 1300119 | E12: 中貨 | F12: 中國豬肉 | G12: 五花肉 | I12: 急凍肉類
A13: 遼寧欣城帶骨雞全腿 200-220G|15KG | B13: 1300603036 | D13: 1300131 | E13: 中貨 | F13: 中國豬肉 | G13: 豬肝 | I13: 急凍肉類
A14: 遼寧欣城帶骨雞全腿 220-240G|15KG | B14: 1300603037 | D14: 1300201 | E14: 西貨 | F14: 外國豬肉 | G14: 一號肉 | I14: 急凍肉類
... A151: 山東全淨膛鴨|10.4KG (1.3KG/只) | B151: 1300901054 | D151: 1310101 | E151: 預製菜 | F151: 終端凍品 | G151: 麵點類.水餃雲吞餛飩 | I151: 急凍面點
A152: 華英帶骨鴨腿|10KG (200-220G/只) | B152: 1300902002 | D152: 13102 | E152: 預製菜 | F152: 終端凍品 | G152: 丸類
A153: 華英帶骨鴨腿|10KG (220-240G/只) | B153: 1300902003 | D153: 1310201 | E153: 預製菜 | F153: 終端凍品 | G153: 丸類.牛肉丸 | I153: 急凍肉類
A154: 華英帶骨鴨腿|10KG (260-280G/只) | B154: 1300902006 | D154: 13103 | E154: 預製菜 | F154: 終端凍品 | G154: 預製
A155: 山東帶骨鴨腿|10KG（200-220G/只） | B155: 1300902010 | D155: 1310301 | E155: 預製菜 | F155: 終端凍品 | G155: 預製菜類.豬肉類 | I155: 加熱即食
A156: 山東帶骨鴨腿|10KG（220-240G/只） | B156: 1300902011 | D156: 1310302 | E156: 預製菜 | F156: 終端凍品 | G156: 預製菜類.雞肉類 | I156: 加熱即食
A157: 山東帶骨鴨腿|10KG（240-260G/只） | B157: 1300902013 | D157: 1310303 | E157: 預製菜 | F157: 終端凍品 | G157: 預製菜類.鴨肉類 | I157: 加熱即食
A158: 華英鴨胸肉|10KG 200-220G/塊) | B158: 1300903002 | D158: 1310304 | E158: 預製菜 | F158: 終端凍品 | G158: 預製菜類.小食類 | I158: 加熱即食
A159: 華英鴨胸肉|10KG 220-240G/塊) | B159: 1300903003 | D159: 1310305 | E159: 預製菜 | F159: 終端凍品 | G159: 預製菜類.樣品 | I159: 加熱即食
A160: 山東鴨胸肉|10KG(200-220克/塊) | B160: 1300903005 | D160: 1310306 | E160: 預製菜 | F160: 終端凍品 | G160: 預製菜類.牛肉類 | I160: 急凍肉類
A161: 山東IQF鴨胸肉|10KG(1K*10) | B161: 1300903010 | D161: 1310307 | E161: 預製菜 | F161: 終端凍品 | G161: 預製菜類.湯煲類 | I161: 急凍肉類
A162: 華英IQF鴨小胸|10KG(1K*10) | B162: 1300903011 | D162: 13104 | E162: 預製菜 | F162: 終端凍品 | G162: 凍肉
A163: 山東煙熏鴨胸肉|10KG (200-220G/塊)日文包裝 | B163: 1300904016 | D163: 1310401 | E163: 中貨 | F163: 終端凍品 | G163: 凍肉加工品.中國羊肉 | I163: 急凍肉類
A164: 山東煙熏鴨胸肉|10KG (220-240G/塊)日文包裝 | B164: 1300904017 | D164: 1310402 | E164: 中貨 | F164: 終端凍品 | G164: 凍肉加工品.中國牛肉 | I164: 急凍肉類
A165: 山東煙熏鴨胸肉|10KG (240-260G/塊)日文包裝 | B165: 1300904021 | D165: 13105 | E165: 預製菜 | F165: 終端凍品 | G165: 腸類
A166: 華英煙熏鴨胸肉|10KG (200-220G/塊)日文包裝 | B166: 1300904022 | D166: 1310501 | E166: 預製菜 | F166: 終端凍品 | G166: 腸類.雞肉腸 | I166: 急凍肉類
A167: 華英煙熏鴨胸肉|10KG (220-240G/塊)日文包裝 | B167: 1300904023 | D167: 13106 | E167: 預製菜 | F167: 終端凍品 | G167: 乳製品
A168: 華英煙熏鴨胸肉|10KG (240-260G/塊)日文包裝 | B168: 1300904024 | D168: 1310601 | E168: 預製菜 | F168: 終端凍品 | G168: 乳製品.芝士 | I168: 零食罐頭
A169: 河南華英凍鴨舌(無鬚)|10KG | B169: 1300913005 | D169: 13107 | E169: 預製菜 | F169: 終端凍品 | G169: 凍海產品
A170: 河南華英凍鴨肝|10KG | B170: 1300917001 | D170: 1310701 | E170: 預製菜 | F170: 終端凍品 | G170: 凍海產品.魚類 | I170: 急凍水產
A171: 河南華英凍鴨腎|10KG | B171: 1300917002 | D171: 13108 | E171: 預製菜 | F171: 終端凍品 | G171: 乾海產類
A172: 河南華英凍鴨心|10KG | B172: 1300920001 | D172: 1310801 | E172: 預製菜 | F172: 終端凍品 | G172: 乾海產類.其他 | I172: 急凍水產
A173: 八合里牛肉丸(零售裝) | B173: 1310201019 | D173: 13109 | E173: 預製菜 | F173: 終端凍品 | G173: 其他冷凍即食類
A174: 八合里牛筋丸(零售裝) | B174: 1310201020 | D174: 1310902 | E174: 預製菜 | F174: 終端凍品 | G174: 其他冷凍即食類.即食海產類 | I174: 加熱即食
A175: 八合里黑椒牛筋丸(零售裝) | B175: 1310201021 | D175: 18001 | E175: 水產 | F175: 水產 | G175: 魚
A176: 八合里牛肉丸(業務裝) | B176: 1310201022 | D176: 1800102 | E176: 水產 | F176: 水產 | G176: 魚.鯰魚柳 | I176: 急凍水產
...
